new new logs

==> Your service is live ðŸŽ‰
[2025-05-20 12:07:29 +0000] [26] [ERROR] Exception in worker process
Traceback (most recent call last):
  File "/usr/local/lib/python3.8/site-packages/gunicorn/arbiter.py", line 583, in spawn_worker
    worker.init_process()
  File "/usr/local/lib/python3.8/site-packages/gunicorn/workers/gthread.py", line 104, in init_process
    super(ThreadWorker, self).init_process()
  File "/usr/local/lib/python3.8/site-packages/gunicorn/workers/base.py", line 129, in init_process
    self.load_wsgi()
  File "/usr/local/lib/python3.8/site-packages/gunicorn/workers/base.py", line 138, in load_wsgi
    self.wsgi = self.app.wsgi()
  File "/usr/local/lib/python3.8/site-packages/gunicorn/app/base.py", line 67, in wsgi
    self.callable = self.load()
  File "/usr/local/lib/python3.8/site-packages/gunicorn/app/wsgiapp.py", line 52, in load
    return self.load_wsgiapp()
  File "/usr/local/lib/python3.8/site-packages/gunicorn/app/wsgiapp.py", line 41, in load_wsgiapp
    return util.import_app(self.app_uri)
  File "/usr/local/lib/python3.8/site-packages/gunicorn/util.py", line 350, in import_app
    __import__(module)
  File "/app/manage.py", line 10, in <module>
    from app import create_app, db
  File "/app/app/__init__.py", line 5, in <module>
    from flask_bootstrap import Bootstrap5
ModuleNotFoundError: No module named 'flask_bootstrap'
[2025-05-20 12:07:29 +0000] [26] [INFO] Worker exiting (pid: 26)
[2025-05-20 12:07:29 +0000] [25] [ERROR] Exception in worker process
Traceback (most recent call last):
  File "/usr/local/lib/python3.8/site-packages/gunicorn/arbiter.py", line 583, in spawn_worker
    worker.init_process()
  File "/usr/local/lib/python3.8/site-packages/gunicorn/workers/gthread.py", line 104, in init_process
    super(ThreadWorker, self).init_process()
  File "/usr/local/lib/python3.8/site-packages/gunicorn/workers/base.py", line 129, in init_process
    self.load_wsgi()
  File "/usr/local/lib/python3.8/site-packages/gunicorn/workers/base.py", line 138, in load_wsgi
    self.wsgi = self.app.wsgi()
  File "/usr/local/lib/python3.8/site-packages/gunicorn/app/base.py", line 67, in wsgi
    self.callable = self.load()
  File "/usr/local/lib/python3.8/site-packages/gunicorn/app/wsgiapp.py", line 52, in load
    return self.load_wsgiapp()
  File "/usr/local/lib/python3.8/site-packages/gunicorn/app/wsgiapp.py", line 41, in load_wsgiapp
    return util.import_app(self.app_uri)
  File "/usr/local/lib/python3.8/site-packages/gunicorn/util.py", line 350, in import_app
    __import__(module)
  File "/app/manage.py", line 10, in <module>
    from app import create_app, db
  File "/app/app/__init__.py", line 5, in <module>
    from flask_bootstrap import Bootstrap5
ModuleNotFoundError: No module named 'flask_bootstrap'
[2025-05-20 12:07:29 +0000] [25] [INFO] Worker exiting (pid: 25)
/usr/local/lib/python3.8/os.py:1023: RuntimeWarning: line buffering (buffering=1) isn't supported in binary mode, the default buffer size will be used
  return io.open(fd, *args, **kwargs)
Traceback (most recent call last):
  File "/usr/local/lib/python3.8/site-packages/gunicorn/arbiter.py", line 210, in run
    self.sleep()
  File "/usr/local/lib/python3.8/site-packages/gunicorn/arbiter.py", line 360, in sleep
    ready = select.select([self.PIPE[0]], [], [], 1.0)
  File "/usr/local/lib/python3.8/site-packages/gunicorn/arbiter.py", line 245, in handle_chld
    self.reap_workers()
  File "/usr/local/lib/python3.8/site-packages/gunicorn/arbiter.py", line 525, in reap_workers
    raise HaltServer(reason, self.WORKER_BOOT_ERROR)
gunicorn.errors.HaltServer: <HaltServer 'Worker failed to boot.' 3>
During handling of the above exception, another exception occurred:
Traceback (most recent call last):
  File "/usr/local/bin/gunicorn", line 8, in <module>
    sys.exit(run())
  File "/usr/local/lib/python3.8/site-packages/gunicorn/app/wsgiapp.py", line 61, in run
    WSGIApplication("%(prog)s [OPTIONS] [APP_MODULE]").run()
  File "/usr/local/lib/python3.8/site-packages/gunicorn/app/base.py", line 223, in run
    super(Application, self).run()
  File "/usr/local/lib/python3.8/site-packages/gunicorn/app/base.py", line 72, in run
    Arbiter(self).run()
  File "/usr/local/lib/python3.8/site-packages/gunicorn/arbiter.py", line 232, in run
    self.halt(reason=inst.reason, exit_status=inst.exit_status)
  File "/usr/local/lib/python3.8/site-packages/gunicorn/arbiter.py", line 345, in halt
    self.stop()
  File "/usr/local/lib/python3.8/site-packages/gunicorn/arbiter.py", line 393, in stop
    time.sleep(0.1)
  File "/usr/local/lib/python3.8/site-packages/gunicorn/arbiter.py", line 245, in handle_chld
    self.reap_workers()
  File "/usr/local/lib/python3.8/site-packages/gunicorn/arbiter.py", line 525, in reap_workers
    raise HaltServer(reason, self.WORKER_BOOT_ERROR)
gunicorn.errors.HaltServer: <HaltServer 'Worker failed to boot.' 3>
[2025-05-20 12:07:34 +0000] [6] [INFO] Starting gunicorn 19.9.0
[2025-05-20 12:07:34 +0000] [6] [INFO] Listening at: http://0.0.0.0:5000 (6)
[2025-05-20 12:07:34 +0000] [6] [INFO] Using worker: threads
/usr/local/lib/python3.8/os.py:1023: RuntimeWarning: line buffering (buffering=1) isn't supported in binary mode, the default buffer size will be used
  return io.open(fd, *args, **kwargs)
[2025-05-20 12:07:34 +0000] [8] [INFO] Booting worker with pid: 8
/usr/local/lib/python3.8/os.py:1023: RuntimeWarning: line buffering (buffering=1) isn't supported in binary mode, the default buffer size will be used
  return io.open(fd, *args, **kwargs)
[2025-05-20 12:07:34 +0000] [9] [INFO] Booting worker with pid: 9
[2025-05-20 12:07:38 +0000] [8] [ERROR] Exception in worker process
Traceback (most recent call last):
  File "/usr/local/lib/python3.8/site-packages/gunicorn/arbiter.py", line 583, in spawn_worker
    worker.init_process()
  File "/usr/local/lib/python3.8/site-packages/gunicorn/workers/gthread.py", line 104, in init_process
    super(ThreadWorker, self).init_process()
  File "/usr/local/lib/python3.8/site-packages/gunicorn/workers/base.py", line 129, in init_process
    self.load_wsgi()
  File "/usr/local/lib/python3.8/site-packages/gunicorn/workers/base.py", line 138, in load_wsgi
    self.wsgi = self.app.wsgi()
  File "/usr/local/lib/python3.8/site-packages/gunicorn/app/base.py", line 67, in wsgi
    self.callable = self.load()
  File "/usr/local/lib/python3.8/site-packages/gunicorn/app/wsgiapp.py", line 52, in load
    return self.load_wsgiapp()
  File "/usr/local/lib/python3.8/site-packages/gunicorn/app/wsgiapp.py", line 41, in load_wsgiapp
    return util.import_app(self.app_uri)
  File "/usr/local/lib/python3.8/site-packages/gunicorn/util.py", line 350, in import_app
    __import__(module)
  File "/app/manage.py", line 10, in <module>
    from app import create_app, db
  File "/app/app/__init__.py", line 5, in <module>
    from flask_bootstrap import Bootstrap5
ModuleNotFoundError: No module named 'flask_bootstrap'
[2025-05-20 12:07:38 +0000] [8] [INFO] Worker exiting (pid: 8)
[2025-05-20 12:07:38 +0000] [9] [ERROR] Exception in worker process
Traceback (most recent call last):
  File "/usr/local/lib/python3.8/site-packages/gunicorn/arbiter.py", line 583, in spawn_worker
    worker.init_process()
  File "/usr/local/lib/python3.8/site-packages/gunicorn/workers/gthread.py", line 104, in init_process
    super(ThreadWorker, self).init_process()
  File "/usr/local/lib/python3.8/site-packages/gunicorn/workers/base.py", line 129, in init_process
    self.load_wsgi()
  File "/usr/local/lib/python3.8/site-packages/gunicorn/workers/base.py", line 138, in load_wsgi
    self.wsgi = self.app.wsgi()
  File "/usr/local/lib/python3.8/site-packages/gunicorn/app/base.py", line 67, in wsgi
    self.callable = self.load()
  File "/usr/local/lib/python3.8/site-packages/gunicorn/app/wsgiapp.py", line 52, in load
    return self.load_wsgiapp()
  File "/usr/local/lib/python3.8/site-packages/gunicorn/app/wsgiapp.py", line 41, in load_wsgiapp
    return util.import_app(self.app_uri)
  File "/usr/local/lib/python3.8/site-packages/gunicorn/util.py", line 350, in import_app
    __import__(module)
  File "/app/manage.py", line 10, in <module>
    from app import create_app, db
  File "/app/app/__init__.py", line 5, in <module>
    from flask_bootstrap import Bootstrap5
ModuleNotFoundError: No module named 'flask_bootstrap'
[2025-05-20 12:07:38 +0000] [9] [INFO] Worker exiting (pid: 9)
/usr/local/lib/python3.8/os.py:1023: RuntimeWarning: line buffering (buffering=1) isn't supported in binary mode, the default buffer size will be used
  return io.open(fd, *args, **kwargs)
[2025-05-20 12:07:40 +0000] [6] [INFO] Shutting down: Master
[2025-05-20 12:07:40 +0000] [6] [INFO] Reason: Worker failed to boot.
[2025-05-20 12:08:01 +0000] [7] [INFO] Starting gunicorn 19.9.0
[2025-05-20 12:08:01 +0000] [7] [INFO] Listening at: http://0.0.0.0:5000 (7)
[2025-05-20 12:08:01 +0000] [7] [INFO] Using worker: threads
/usr/local/lib/python3.8/os.py:1023: RuntimeWarning: line buffering (buffering=1) isn't supported in binary mode, the default buffer size will be used
  return io.open(fd, *args, **kwargs)
[2025-05-20 12:08:01 +0000] [25] [INFO] Booting worker with pid: 25
/usr/local/lib/python3.8/os.py:1023: RuntimeWarning: line buffering (buffering=1) isn't supported in binary mode, the default buffer size will be used
  return io.open(fd, *args, **kwargs)
[2025-05-20 12:08:01 +0000] [26] [INFO] Booting worker with pid: 26
[2025-05-20 12:08:06 +0000] [26] [ERROR] Exception in worker process
Traceback (most recent call last):
  File "/usr/local/lib/python3.8/site-packages/gunicorn/arbiter.py", line 583, in spawn_worker
    worker.init_process()
  File "/usr/local/lib/python3.8/site-packages/gunicorn/workers/gthread.py", line 104, in init_process
    super(ThreadWorker, self).init_process()
  File "/usr/local/lib/python3.8/site-packages/gunicorn/workers/base.py", line 129, in init_process
    self.load_wsgi()
  File "/usr/local/lib/python3.8/site-packages/gunicorn/workers/base.py", line 138, in load_wsgi
    self.wsgi = self.app.wsgi()
  File "/usr/local/lib/python3.8/site-packages/gunicorn/app/base.py", line 67, in wsgi
    self.callable = self.load()
  File "/usr/local/lib/python3.8/site-packages/gunicorn/app/wsgiapp.py", line 52, in load
    return self.load_wsgiapp()
  File "/usr/local/lib/python3.8/site-packages/gunicorn/app/wsgiapp.py", line 41, in load_wsgiapp
    return util.import_app(self.app_uri)
  File "/usr/local/lib/python3.8/site-packages/gunicorn/util.py", line 350, in import_app
    __import__(module)
  File "/app/manage.py", line 10, in <module>
    from app import create_app, db
  File "/app/app/__init__.py", line 5, in <module>
    from flask_bootstrap import Bootstrap5
ModuleNotFoundError: No module named 'flask_bootstrap'
[2025-05-20 12:08:06 +0000] [26] [INFO] Worker exiting (pid: 26)
[2025-05-20 12:08:06 +0000] [25] [ERROR] Exception in worker process
Traceback (most recent call last):
  File "/usr/local/lib/python3.8/site-packages/gunicorn/arbiter.py", line 583, in spawn_worker
    worker.init_process()
  File "/usr/local/lib/python3.8/site-packages/gunicorn/workers/gthread.py", line 104, in init_process
    super(ThreadWorker, self).init_process()
  File "/usr/local/lib/python3.8/site-packages/gunicorn/workers/base.py", line 129, in init_process
    self.load_wsgi()
  File "/usr/local/lib/python3.8/site-packages/gunicorn/workers/base.py", line 138, in load_wsgi
    self.wsgi = self.app.wsgi()
  File "/usr/local/lib/python3.8/site-packages/gunicorn/app/base.py", line 67, in wsgi
    self.callable = self.load()
  File "/usr/local/lib/python3.8/site-packages/gunicorn/app/wsgiapp.py", line 52, in load
    return self.load_wsgiapp()
  File "/usr/local/lib/python3.8/site-packages/gunicorn/app/wsgiapp.py", line 41, in load_wsgiapp
    return util.import_app(self.app_uri)
  File "/usr/local/lib/python3.8/site-packages/gunicorn/util.py", line 350, in import_app
    __import__(module)
  File "/app/manage.py", line 10, in <module>
    from app import create_app, db
  File "/app/app/__init__.py", line 5, in <module>
    from flask_bootstrap import Bootstrap5
ModuleNotFoundError: No module named 'flask_bootstrap'
[2025-05-20 12:08:06 +0000] [25] [INFO] Worker exiting (pid: 25)
/usr/local/lib/python3.8/os.py:1023: RuntimeWarning: line buffering (buffering=1) isn't supported in binary mode, the default buffer size will be used
  return io.open(fd, *args, **kwargs)
Traceback (most recent call last):
  File "/usr/local/lib/python3.8/site-packages/gunicorn/arbiter.py", line 210, in run
    self.sleep()
  File "/usr/local/lib/python3.8/site-packages/gunicorn/arbiter.py", line 360, in sleep
    ready = select.select([self.PIPE[0]], [], [], 1.0)
  File "/usr/local/lib/python3.8/site-packages/gunicorn/arbiter.py", line 245, in handle_chld
    self.reap_workers()
  File "/usr/local/lib/python3.8/site-packages/gunicorn/arbiter.py", line 525, in reap_workers
    raise HaltServer(reason, self.WORKER_BOOT_ERROR)
gunicorn.errors.HaltServer: <HaltServer 'Worker failed to boot.' 3>
During handling of the above exception, another exception occurred:
Traceback (most recent call last):
  File "/usr/local/bin/gunicorn", line 8, in <module>
    sys.exit(run())
  File "/usr/local/lib/python3.8/site-packages/gunicorn/app/wsgiapp.py", line 61, in run
    WSGIApplication("%(prog)s [OPTIONS] [APP_MODULE]").run()
  File "/usr/local/lib/python3.8/site-packages/gunicorn/app/base.py", line 223, in run
    super(Application, self).run()
  File "/usr/local/lib/python3.8/site-packages/gunicorn/app/base.py", line 72, in run
    Arbiter(self).run()
  File "/usr/local/lib/python3.8/site-packages/gunicorn/arbiter.py", line 232, in run
    self.halt(reason=inst.reason, exit_status=inst.exit_status)
  File "/usr/local/lib/python3.8/site-packages/gunicorn/arbiter.py", line 345, in halt
    self.stop()
  File "/usr/local/lib/python3.8/site-packages/gunicorn/arbiter.py", line 393, in stop
    time.sleep(0.1)
  File "/usr/local/lib/python3.8/site-packages/gunicorn/arbiter.py", line 245, in handle_chld
    self.reap_workers()
  File "/usr/local/lib/python3.8/site-packages/gunicorn/arbiter.py", line 525, in reap_workers
    raise HaltServer(reason, self.WORKER_BOOT_ERROR)
gunicorn.errors.HaltServer: <HaltServer 'Worker failed to boot.' 3>
==> No open ports detected, continuing to scan...
==> Docs on specifying a port: https://render.com/docs/web-services#port-binding